[2023-10-09T21:29:58.987+0200] {taskinstance.py:1157} INFO - Dependencies all met for dep_context=non-requeueable deps ti=<TaskInstance: CleanData.filter scheduled__2023-10-09T00:30:00+00:00 [queued]>
[2023-10-09T21:29:58.990+0200] {taskinstance.py:1157} INFO - Dependencies all met for dep_context=requeueable deps ti=<TaskInstance: CleanData.filter scheduled__2023-10-09T00:30:00+00:00 [queued]>
[2023-10-09T21:29:58.990+0200] {taskinstance.py:1359} INFO - Starting attempt 1 of 2
[2023-10-09T21:29:59.001+0200] {taskinstance.py:1380} INFO - Executing <Task(PythonOperator): filter> on 2023-10-09 00:30:00+00:00
[2023-10-09T21:29:59.006+0200] {standard_task_runner.py:57} INFO - Started process 34321 to run task
[2023-10-09T21:29:59.008+0200] {standard_task_runner.py:84} INFO - Running: ['airflow', 'tasks', 'run', 'CleanData', 'filter', 'scheduled__2023-10-09T00:30:00+00:00', '--job-id', '2626', '--raw', '--subdir', 'DAGS_FOLDER/cleaningDatadag.py', '--cfg-path', '/tmp/tmps0hmlq9x']
[2023-10-09T21:29:59.009+0200] {standard_task_runner.py:85} INFO - Job 2626: Subtask filter
[2023-10-09T21:29:59.034+0200] {task_command.py:415} INFO - Running <TaskInstance: CleanData.filter scheduled__2023-10-09T00:30:00+00:00 [running]> on host radtrz-B450-AORUS-ELITE
[2023-10-09T21:29:59.079+0200] {taskinstance.py:1660} INFO - Exporting env vars: AIRFLOW_CTX_DAG_OWNER='radtrz' AIRFLOW_CTX_DAG_ID='CleanData' AIRFLOW_CTX_TASK_ID='filter' AIRFLOW_CTX_EXECUTION_DATE='2023-10-09T00:30:00+00:00' AIRFLOW_CTX_TRY_NUMBER='1' AIRFLOW_CTX_DAG_RUN_ID='scheduled__2023-10-09T00:30:00+00:00'
[2023-10-09T21:29:59.136+0200] {taskinstance.py:1935} ERROR - Task failed with exception
Traceback (most recent call last):
  File "/home/radtrz/.local/lib/python3.10/site-packages/airflow/operators/python.py", line 192, in execute
    return_value = self.execute_callable()
  File "/home/radtrz/.local/lib/python3.10/site-packages/airflow/operators/python.py", line 209, in execute_callable
    return self.python_callable(*self.op_args, **self.op_kwargs)
  File "/home/radtrz/airflow/dags/cleaningDatadag.py", line 28, in filterData
    tofrom = df[df(['started_at']>fromd) & (df(['started_at']<tod))]
TypeError: '>' not supported between instances of 'list' and 'str'
[2023-10-09T21:29:59.138+0200] {taskinstance.py:1398} INFO - Marking task as UP_FOR_RETRY. dag_id=CleanData, task_id=filter, execution_date=20231009T003000, start_date=20231009T192958, end_date=20231009T192959
[2023-10-09T21:29:59.148+0200] {standard_task_runner.py:104} ERROR - Failed to execute job 2626 for task filter ('>' not supported between instances of 'list' and 'str'; 34321)
[2023-10-09T21:29:59.180+0200] {local_task_job_runner.py:228} INFO - Task exited with return code 1
[2023-10-09T21:29:59.197+0200] {taskinstance.py:2776} INFO - 0 downstream tasks scheduled from follow-on schedule check
