[2023-10-09T21:30:06.536+0200] {taskinstance.py:1157} INFO - Dependencies all met for dep_context=non-requeueable deps ti=<TaskInstance: CleanData.filter scheduled__2023-10-09T00:45:00+00:00 [queued]>
[2023-10-09T21:30:06.539+0200] {taskinstance.py:1157} INFO - Dependencies all met for dep_context=requeueable deps ti=<TaskInstance: CleanData.filter scheduled__2023-10-09T00:45:00+00:00 [queued]>
[2023-10-09T21:30:06.539+0200] {taskinstance.py:1359} INFO - Starting attempt 1 of 2
[2023-10-09T21:30:06.550+0200] {taskinstance.py:1380} INFO - Executing <Task(PythonOperator): filter> on 2023-10-09 00:45:00+00:00
[2023-10-09T21:30:06.554+0200] {standard_task_runner.py:57} INFO - Started process 34409 to run task
[2023-10-09T21:30:06.556+0200] {standard_task_runner.py:84} INFO - Running: ['airflow', 'tasks', 'run', 'CleanData', 'filter', 'scheduled__2023-10-09T00:45:00+00:00', '--job-id', '2631', '--raw', '--subdir', 'DAGS_FOLDER/cleaningDatadag.py', '--cfg-path', '/tmp/tmp38u_ssvf']
[2023-10-09T21:30:06.557+0200] {standard_task_runner.py:85} INFO - Job 2631: Subtask filter
[2023-10-09T21:30:06.578+0200] {task_command.py:415} INFO - Running <TaskInstance: CleanData.filter scheduled__2023-10-09T00:45:00+00:00 [running]> on host radtrz-B450-AORUS-ELITE
[2023-10-09T21:30:06.617+0200] {taskinstance.py:1660} INFO - Exporting env vars: AIRFLOW_CTX_DAG_OWNER='radtrz' AIRFLOW_CTX_DAG_ID='CleanData' AIRFLOW_CTX_TASK_ID='filter' AIRFLOW_CTX_EXECUTION_DATE='2023-10-09T00:45:00+00:00' AIRFLOW_CTX_TRY_NUMBER='1' AIRFLOW_CTX_DAG_RUN_ID='scheduled__2023-10-09T00:45:00+00:00'
[2023-10-09T21:30:06.676+0200] {taskinstance.py:1935} ERROR - Task failed with exception
Traceback (most recent call last):
  File "/home/radtrz/.local/lib/python3.10/site-packages/airflow/operators/python.py", line 192, in execute
    return_value = self.execute_callable()
  File "/home/radtrz/.local/lib/python3.10/site-packages/airflow/operators/python.py", line 209, in execute_callable
    return self.python_callable(*self.op_args, **self.op_kwargs)
  File "/home/radtrz/airflow/dags/cleaningDatadag.py", line 28, in filterData
    tofrom = df[df(['started_at']>fromd) & (df(['started_at']<tod))]
TypeError: '>' not supported between instances of 'list' and 'str'
[2023-10-09T21:30:06.678+0200] {taskinstance.py:1398} INFO - Marking task as UP_FOR_RETRY. dag_id=CleanData, task_id=filter, execution_date=20231009T004500, start_date=20231009T193006, end_date=20231009T193006
[2023-10-09T21:30:06.684+0200] {standard_task_runner.py:104} ERROR - Failed to execute job 2631 for task filter ('>' not supported between instances of 'list' and 'str'; 34409)
[2023-10-09T21:30:06.728+0200] {local_task_job_runner.py:228} INFO - Task exited with return code 1
[2023-10-09T21:30:06.745+0200] {taskinstance.py:2776} INFO - 0 downstream tasks scheduled from follow-on schedule check
