[2023-10-09T21:24:38.945+0200] {taskinstance.py:1157} INFO - Dependencies all met for dep_context=non-requeueable deps ti=<TaskInstance: CleanData.clean scheduled__2023-10-09T00:45:00+00:00 [queued]>
[2023-10-09T21:24:38.948+0200] {taskinstance.py:1157} INFO - Dependencies all met for dep_context=requeueable deps ti=<TaskInstance: CleanData.clean scheduled__2023-10-09T00:45:00+00:00 [queued]>
[2023-10-09T21:24:38.948+0200] {taskinstance.py:1359} INFO - Starting attempt 1 of 2
[2023-10-09T21:24:38.956+0200] {taskinstance.py:1380} INFO - Executing <Task(PythonOperator): clean> on 2023-10-09 00:45:00+00:00
[2023-10-09T21:24:38.960+0200] {standard_task_runner.py:57} INFO - Started process 33356 to run task
[2023-10-09T21:24:38.963+0200] {standard_task_runner.py:84} INFO - Running: ['airflow', 'tasks', 'run', 'CleanData', 'clean', 'scheduled__2023-10-09T00:45:00+00:00', '--job-id', '2599', '--raw', '--subdir', 'DAGS_FOLDER/cleaningDatadag.py', '--cfg-path', '/tmp/tmpiw4ahs59']
[2023-10-09T21:24:38.964+0200] {standard_task_runner.py:85} INFO - Job 2599: Subtask clean
[2023-10-09T21:24:38.986+0200] {task_command.py:415} INFO - Running <TaskInstance: CleanData.clean scheduled__2023-10-09T00:45:00+00:00 [running]> on host radtrz-B450-AORUS-ELITE
[2023-10-09T21:24:39.026+0200] {taskinstance.py:1660} INFO - Exporting env vars: AIRFLOW_CTX_DAG_OWNER='radtrz' AIRFLOW_CTX_DAG_ID='CleanData' AIRFLOW_CTX_TASK_ID='clean' AIRFLOW_CTX_EXECUTION_DATE='2023-10-09T00:45:00+00:00' AIRFLOW_CTX_TRY_NUMBER='1' AIRFLOW_CTX_DAG_RUN_ID='scheduled__2023-10-09T00:45:00+00:00'
[2023-10-09T21:24:39.027+0200] {taskinstance.py:1935} ERROR - Task failed with exception
Traceback (most recent call last):
  File "/home/radtrz/.local/lib/python3.10/site-packages/airflow/operators/python.py", line 192, in execute
    return_value = self.execute_callable()
  File "/home/radtrz/.local/lib/python3.10/site-packages/airflow/operators/python.py", line 209, in execute_callable
    return self.python_callable(*self.op_args, **self.op_kwargs)
  File "/home/radtrz/airflow/dags/cleaningDatadag.py", line 17, in cleanScooter
    df = pd.read_csv('scooter.csv')
  File "/home/radtrz/.local/lib/python3.10/site-packages/pandas/io/parsers/readers.py", line 948, in read_csv
    return _read(filepath_or_buffer, kwds)
  File "/home/radtrz/.local/lib/python3.10/site-packages/pandas/io/parsers/readers.py", line 611, in _read
    parser = TextFileReader(filepath_or_buffer, **kwds)
  File "/home/radtrz/.local/lib/python3.10/site-packages/pandas/io/parsers/readers.py", line 1448, in __init__
    self._engine = self._make_engine(f, self.engine)
  File "/home/radtrz/.local/lib/python3.10/site-packages/pandas/io/parsers/readers.py", line 1705, in _make_engine
    self.handles = get_handle(
  File "/home/radtrz/.local/lib/python3.10/site-packages/pandas/io/common.py", line 863, in get_handle
    handle = open(
FileNotFoundError: [Errno 2] No such file or directory: 'scooter.csv'
[2023-10-09T21:24:39.030+0200] {taskinstance.py:1398} INFO - Marking task as UP_FOR_RETRY. dag_id=CleanData, task_id=clean, execution_date=20231009T004500, start_date=20231009T192438, end_date=20231009T192439
[2023-10-09T21:24:39.037+0200] {standard_task_runner.py:104} ERROR - Failed to execute job 2599 for task clean ([Errno 2] No such file or directory: 'scooter.csv'; 33356)
[2023-10-09T21:24:39.054+0200] {local_task_job_runner.py:228} INFO - Task exited with return code 1
[2023-10-09T21:24:39.065+0200] {taskinstance.py:2776} INFO - 0 downstream tasks scheduled from follow-on schedule check
